{
  "nbformat": 4,
  "nbformat_minor": 0,
  "metadata": {
    "colab": {
      "name": "X-ray-implement.ipynb",
      "provenance": [],
      "authorship_tag": "ABX9TyNEoeLjSL8hwUhka7RMkgCU",
      "include_colab_link": true
    },
    "kernelspec": {
      "name": "python3",
      "display_name": "Python 3"
    },
    "language_info": {
      "name": "python"
    }
  },
  "cells": [
    {
      "cell_type": "markdown",
      "metadata": {
        "id": "view-in-github",
        "colab_type": "text"
      },
      "source": [
        "<a href=\"https://colab.research.google.com/github/keplercore/X-ray-project/blob/main/X_ray_implement.ipynb\" target=\"_parent\"><img src=\"https://colab.research.google.com/assets/colab-badge.svg\" alt=\"Open In Colab\"/></a>"
      ]
    },
    {
      "cell_type": "code",
      "source": [
        "from google.colab import drive\n",
        "drive.mount('/content/drive')"
      ],
      "metadata": {
        "colab": {
          "base_uri": "https://localhost:8080/"
        },
        "id": "zcE8j-EGoIsj",
        "outputId": "19bb7aa7-2b0f-4eef-cbf5-d95e7061d7be"
      },
      "execution_count": 23,
      "outputs": [
        {
          "output_type": "stream",
          "name": "stdout",
          "text": [
            "Drive already mounted at /content/drive; to attempt to forcibly remount, call drive.mount(\"/content/drive\", force_remount=True).\n"
          ]
        }
      ]
    },
    {
      "cell_type": "code",
      "source": [
        "import cv2"
      ],
      "metadata": {
        "id": "agKCT31fsqE5"
      },
      "execution_count": 29,
      "outputs": []
    },
    {
      "cell_type": "code",
      "execution_count": 30,
      "metadata": {
        "id": "nlqWTIRbgC6V"
      },
      "outputs": [],
      "source": [
        "import tensorflow as tf\n",
        "from tensorflow import keras\n",
        "reconstructed_model = keras.models.load_model(\"/content/drive/MyDrive/ColabNotebooks\")"
      ]
    },
    {
      "cell_type": "code",
      "source": [
        "img = cv2.imread(\"person1_virus_6.jpeg\")\n",
        "img = cv2.resize(img, (150,150))\n",
        "img.shape"
      ],
      "metadata": {
        "colab": {
          "base_uri": "https://localhost:8080/"
        },
        "id": "FGy6MjbOlPNF",
        "outputId": "9dfbad77-5226-49c6-98a6-ae4549ae366c"
      },
      "execution_count": 41,
      "outputs": [
        {
          "output_type": "execute_result",
          "data": {
            "text/plain": [
              "(150, 150, 3)"
            ]
          },
          "metadata": {},
          "execution_count": 41
        }
      ]
    },
    {
      "cell_type": "code",
      "source": [
        "reconstructed_model.predict(img)"
      ],
      "metadata": {
        "colab": {
          "base_uri": "https://localhost:8080/",
          "height": 586
        },
        "outputId": "09daf216-3ff0-4bfd-94fe-d30df6b4b787",
        "id": "DHwyLKc0wKCC"
      },
      "execution_count": 43,
      "outputs": [
        {
          "output_type": "error",
          "ename": "ValueError",
          "evalue": "ignored",
          "traceback": [
            "\u001b[0;31m---------------------------------------------------------------------------\u001b[0m",
            "\u001b[0;31mValueError\u001b[0m                                Traceback (most recent call last)",
            "\u001b[0;32m<ipython-input-43-7b04579d6cb7>\u001b[0m in \u001b[0;36m<module>\u001b[0;34m()\u001b[0m\n\u001b[0;32m----> 1\u001b[0;31m \u001b[0mreconstructed_model\u001b[0m\u001b[0;34m.\u001b[0m\u001b[0mpredict\u001b[0m\u001b[0;34m(\u001b[0m\u001b[0mimg\u001b[0m\u001b[0;34m)\u001b[0m\u001b[0;34m\u001b[0m\u001b[0;34m\u001b[0m\u001b[0m\n\u001b[0m",
            "\u001b[0;32m/usr/local/lib/python3.7/dist-packages/keras/utils/traceback_utils.py\u001b[0m in \u001b[0;36merror_handler\u001b[0;34m(*args, **kwargs)\u001b[0m\n\u001b[1;32m     65\u001b[0m     \u001b[0;32mexcept\u001b[0m \u001b[0mException\u001b[0m \u001b[0;32mas\u001b[0m \u001b[0me\u001b[0m\u001b[0;34m:\u001b[0m  \u001b[0;31m# pylint: disable=broad-except\u001b[0m\u001b[0;34m\u001b[0m\u001b[0;34m\u001b[0m\u001b[0m\n\u001b[1;32m     66\u001b[0m       \u001b[0mfiltered_tb\u001b[0m \u001b[0;34m=\u001b[0m \u001b[0m_process_traceback_frames\u001b[0m\u001b[0;34m(\u001b[0m\u001b[0me\u001b[0m\u001b[0;34m.\u001b[0m\u001b[0m__traceback__\u001b[0m\u001b[0;34m)\u001b[0m\u001b[0;34m\u001b[0m\u001b[0;34m\u001b[0m\u001b[0m\n\u001b[0;32m---> 67\u001b[0;31m       \u001b[0;32mraise\u001b[0m \u001b[0me\u001b[0m\u001b[0;34m.\u001b[0m\u001b[0mwith_traceback\u001b[0m\u001b[0;34m(\u001b[0m\u001b[0mfiltered_tb\u001b[0m\u001b[0;34m)\u001b[0m \u001b[0;32mfrom\u001b[0m \u001b[0;32mNone\u001b[0m\u001b[0;34m\u001b[0m\u001b[0;34m\u001b[0m\u001b[0m\n\u001b[0m\u001b[1;32m     68\u001b[0m     \u001b[0;32mfinally\u001b[0m\u001b[0;34m:\u001b[0m\u001b[0;34m\u001b[0m\u001b[0;34m\u001b[0m\u001b[0m\n\u001b[1;32m     69\u001b[0m       \u001b[0;32mdel\u001b[0m \u001b[0mfiltered_tb\u001b[0m\u001b[0;34m\u001b[0m\u001b[0;34m\u001b[0m\u001b[0m\n",
            "\u001b[0;32m/usr/local/lib/python3.7/dist-packages/tensorflow/python/framework/func_graph.py\u001b[0m in \u001b[0;36mautograph_handler\u001b[0;34m(*args, **kwargs)\u001b[0m\n\u001b[1;32m   1145\u001b[0m           \u001b[0;32mexcept\u001b[0m \u001b[0mException\u001b[0m \u001b[0;32mas\u001b[0m \u001b[0me\u001b[0m\u001b[0;34m:\u001b[0m  \u001b[0;31m# pylint:disable=broad-except\u001b[0m\u001b[0;34m\u001b[0m\u001b[0;34m\u001b[0m\u001b[0m\n\u001b[1;32m   1146\u001b[0m             \u001b[0;32mif\u001b[0m \u001b[0mhasattr\u001b[0m\u001b[0;34m(\u001b[0m\u001b[0me\u001b[0m\u001b[0;34m,\u001b[0m \u001b[0;34m\"ag_error_metadata\"\u001b[0m\u001b[0;34m)\u001b[0m\u001b[0;34m:\u001b[0m\u001b[0;34m\u001b[0m\u001b[0;34m\u001b[0m\u001b[0m\n\u001b[0;32m-> 1147\u001b[0;31m               \u001b[0;32mraise\u001b[0m \u001b[0me\u001b[0m\u001b[0;34m.\u001b[0m\u001b[0mag_error_metadata\u001b[0m\u001b[0;34m.\u001b[0m\u001b[0mto_exception\u001b[0m\u001b[0;34m(\u001b[0m\u001b[0me\u001b[0m\u001b[0;34m)\u001b[0m\u001b[0;34m\u001b[0m\u001b[0;34m\u001b[0m\u001b[0m\n\u001b[0m\u001b[1;32m   1148\u001b[0m             \u001b[0;32melse\u001b[0m\u001b[0;34m:\u001b[0m\u001b[0;34m\u001b[0m\u001b[0;34m\u001b[0m\u001b[0m\n\u001b[1;32m   1149\u001b[0m               \u001b[0;32mraise\u001b[0m\u001b[0;34m\u001b[0m\u001b[0;34m\u001b[0m\u001b[0m\n",
            "\u001b[0;31mValueError\u001b[0m: in user code:\n\n    File \"/usr/local/lib/python3.7/dist-packages/keras/engine/training.py\", line 1801, in predict_function  *\n        return step_function(self, iterator)\n    File \"/usr/local/lib/python3.7/dist-packages/keras/engine/training.py\", line 1790, in step_function  **\n        outputs = model.distribute_strategy.run(run_step, args=(data,))\n    File \"/usr/local/lib/python3.7/dist-packages/keras/engine/training.py\", line 1783, in run_step  **\n        outputs = model.predict_step(data)\n    File \"/usr/local/lib/python3.7/dist-packages/keras/engine/training.py\", line 1751, in predict_step\n        return self(x, training=False)\n    File \"/usr/local/lib/python3.7/dist-packages/keras/utils/traceback_utils.py\", line 67, in error_handler\n        raise e.with_traceback(filtered_tb) from None\n    File \"/usr/local/lib/python3.7/dist-packages/keras/engine/input_spec.py\", line 264, in assert_input_compatibility\n        raise ValueError(f'Input {input_index} of layer \"{layer_name}\" is '\n\n    ValueError: Input 0 of layer \"sequential_5\" is incompatible with the layer: expected shape=(None, 150, 150, 3), found shape=(None, 150, 3)\n"
          ]
        }
      ]
    },
    {
      "cell_type": "code",
      "source": [
        ""
      ],
      "metadata": {
        "id": "QwDif5CSzPwv"
      },
      "execution_count": null,
      "outputs": []
    }
  ]
}